Workbook

Sheet Premissas
A1: RAIJIN — Simulação de agendamento de waves
A2: Modelo visual para as primeiras 50 waves — Bulk / Deep Archive
A4: Parâmetro | B4: Valor | C4: Unidade | D4: Descrição
A5: Quantidade de waves | B5: 50 | C5: waves | D5: Quantidade exibida no cronograma.
A6: Tamanho alvo da wave | B6: 6 | C6: TB | D6: Tamanho inicial de cada wave; em produção pode ser dinâmico.
A7: Vazão efetiva estimada | B7: 1100 | C7: Mbps | D7: Vazão agregada sustentável para todos os workers.
A8: Duração estimada da transferência | B8: =B6*8000000/B7/3600 -> 12.121212 | C8: horas | D8: 6 TB × 8.000.000 Mb/TB ÷ Mbps ÷ 3.600.
A9: Restore Bulk planejado | B9: 48 | C9: horas | D9: Prazo máximo de planejamento para Deep Archive BULK.
A10: Margem operacional | B10: 6 | C10: horas | D10: Folga para polling, variação e retomada.
A11: Lead time | B11: =B9+B10 -> 54 | C11: horas | D11: Antecedência entre solicitação e slot de transferência.
A12: Retenção configurada | B12: 3 | C12: dias | D12: Cópia temporária restaurada disponível no S3.
A13: Retenção equivalente | B13: =B12*24 -> 72 | C13: horas | D13: Convertida para comparar com o lead time.
A14: Janela econômica | B14: =B13-B11 -> 18 | C14: horas | D14: Janela disponível para solicitar o restore com segurança.
A15: Bloco visual da linha do tempo | B15: 3 | C15: horas | D15: Cada célula do Gantt representa este intervalo.
A20: Como ler o cronograma
A21: A wave 001 é solicitada no início do projeto. As waves seguintes são solicitadas a cada duração estimada de transferência. Cada slot de transferência começa após o lead time; isso estabiliza o fluxo e evita que uma disponibilidade antecipada provoque lacuna na wave seguinte. A planilha representa uma programação conservadora: 48h de restore + 6h de margem.

Sheet Cronograma - 50 waves
A1: Cronograma visual — primeiras 50 waves
A2: Restore é solicitado no último momento seguro; a transferência é serializada em uma única wave, usando todos os workers.
J4: Linha do tempo (T+ horas) | K4: 0 | L4: 3 | M4: 6 | N4: 9 | O4: 12 | P4: 15 | Q4: 18 | R4: 21 | S4: 24 | T4: 27 | U4: 30 | V4: 33 | W4: 36 | X4: 39 | Y4: 42 | Z4: 45 | AA4: 48 | AB4: 51 | AC4: 54 | AD4: 57 | AE4: 60 | AF4: 63 | AG4: 66 | AH4: 69 | AI4: 72 | AJ4: 75 | AK4: 78 | AL4: 81 | AM4: 84 | AN4: 87 | AO4: 90 | AP4: 93 | AQ4: 96 | AR4: 99 | AS4: 102 | AT4: 105 | AU4: 108 | AV4: 111 | AW4: 114 | AX4: 117 | AY4: 120 | AZ4: 123 | BA4: 126 | BB4: 129 | BC4: 132 | BD4: 135 | BE4: 138 | BF4: 141 | BG4: 144 | BH4: 147 | BI4: 150 | BJ4: 153 | BK4: 156 | BL4: 159 | BM4: 162 | BN4: 165 | BO4: 168 | BP4: 171 | BQ4: 174 | BR4: 177 | BS4: 180 | BT4: 183 | BU4: 186 | BV4: 189 | BW4: 192 | BX4: 195 | BY4: 198 | BZ4: 201 | CA4: 204 | CB4: 207 | CC4: 210 | CD4: 213 | CE4: 216 | CF4: 219 | CG4: 222 | CH4: 225 | CI4: 228 | CJ4: 231 | CK4: 234 | CL4: 237 | CM4: 240 | CN4: 243 | CO4: 246 | CP4: 249 | CQ4: 252 | CR4: 255 | CS4: 258 | CT4: 261 | CU4: 264 | CV4: 267 | CW4: 270 | CX4: 273 | CY4: 276 | CZ4: 279 | DA4: 282 | DB4: 285 | DC4: 288 | DD4: 291 | DE4: 294 | DF4: 297 | DG4: 300 | DH4: 303 | DI4: 306 | DJ4: 309 | DK4: 312 | DL4: 315 | DM4: 318 | DN4: 321 | DO4: 324 | DP4: 327 | DQ4: 330 | DR4: 333 | DS4: 336 | DT4: 339 | DU4: 342 | DV4: 345 | DW4: 348 | DX4: 351 | DY4: 354 | DZ4: 357 | EA4: 360 | EB4: 363 | EC4: 366 | ED4: 369 | EE4: 372 | EF4: 375 | EG4: 378 | EH4: 381 | EI4: 384 | EJ4: 387 | EK4: 390 | EL4: 393 | EM4: 396 | EN4: 399 | EO4: 402 | EP4: 405 | EQ4: 408 | ER4: 411 | ES4: 414 | ET4: 417 | EU4: 420 | EV4: 423 | EW4: 426 | EX4: 429 | EY4: 432 | EZ4: 435 | FA4: 438 | FB4: 441 | FC4: 444 | FD4: 447 | FE4: 450 | FF4: 453 | FG4: 456 | FH4: 459 | FI4: 462 | FJ4: 465 | FK4: 468 | FL4: 471 | FM4: 474 | FN4: 477 | FO4: 480 | FP4: 483 | FQ4: 486 | FR4: 489 | FS4: 492 | FT4: 495 | FU4: 498 | FV4: 501 | FW4: 504 | FX4: 507 | FY4: 510 | FZ4: 513 | GA4: 516 | GB4: 519 | GC4: 522 | GD4: 525 | GE4: 528 | GF4: 531 | GG4: 534 | GH4: 537 | GI4: 540 | GJ4: 543 | GK4: 546 | GL4: 549 | GM4: 552 | GN4: 555 | GO4: 558 | GP4: 561 | GQ4: 564 | GR4: 567 | GS4: 570 | GT4: 573 | GU4: 576 | GV4: 579 | GW4: 582 | GX4: 585 | GY4: 588 | GZ4: 591 | HA4: 594 | HB4: 597 | HC4: 600 | HD4: 603 | HE4: 606 | HF4: 609 | HG4: 612 | HH4: 615 | HI4: 618 | HJ4: 621 | HK4: 624 | HL4: 627 | HM4: 630 | HN4: 633 | HO4: 636 | HP4: 639 | HQ4: 642 | HR4: 645 | HS4: 648 | HT4: 651 | HU4: 654 | HV4: 657 | HW4: 660 | HX4: 663 | HY4: 666 | HZ4: 669 | IA4: 672
A5: Wave | B5: Vol | C5: Restore solicitado (hora T+) | D5: Disponível previsto (hora T+) | E5: Transferência inicia (hora T+) | F5: Transferência termina (hora T+) | G5: Espera máxima se disponível cedo | H5: Retenção | I5: Situação | J5: Observação
A6: 1 | B6: =Premissas!$B$6 -> 6 | C6: =0*Premissas!$B$8 -> 0 | D6: =C6+Premissas!$B$9 -> 48 | E6: =C6+Premissas!$B$11 -> 54 | F6: =E6+Premissas!$B$8 -> 66.121212 | G6: =Premissas!$B$11 -> 54 | H6: =Premissas!$B$12 -> 3 | I6: PLANEJADA | J6: Slot serial; criação imutável. | K6: =IF(AND(K$4>=$C6,K$4<$D6),"R",IF(AND(K$4>=$D6,K$4<$E6),"P",IF(AND(K$4>=$E6,K$4<$F6),"T",""))) -> R | L6: =IF(AND(L$4>=$C6,L$4<$D6),"R",IF(AND(L$4>=$D6,L$4<$E6),"P",IF(AND(L$4>=$E6,L$4<$F6),"T",""))) -> R | M6: =IF(AND(M$4>=$C6,M$4<$D6),"R",IF(AND(M$4>=$D6,M$4<$E6),"P",IF(AND(M$4>=$E6,M$4<$F6),"T",""))) -> R | N6: =IF(AND(N$4>=$C6,N$4<$D6),"R",IF(AND(N$4>=$D6,N$4<$E6),"P",IF(AND(N$4>=$E6,N$4<$F6),"T",""))) -> R | O6: =IF(AND(O$4>=$C6,O$4<$D6),"R",IF(AND(O$4>=$D6,O$4<$E6),"P",IF(AND(O$4>=$E6,O$4<$F6),"T",""))) -> R | P6: =IF(AND(P$4>=$C6,P$4<$D6),"R",IF(AND(P$4>=$D6,P$4<$E6),"P",IF(AND(P$4>=$E6,P$4<$F6),"T",""))) -> R | Q6: =IF(AND(Q$4>=$C6,Q$4<$D6),"R",IF(AND(Q$4>=$D6,Q$4<$E6),"P",IF(AND(Q$4>=$E6,Q$4<$F6),"T",""))) -> R | R6: =IF(AND(R$4>=$C6,R$4<$D6),"R",IF(AND(R$4>=$D6,R$4<$E6),"P",IF(AND(R$4>=$E6,R$4<$F6),"T",""))) -> R | ... IA6: =IF(AND(IA$4>=$C6,IA$4<$D6),"R",IF(AND(IA$4>=$D6,IA$4<$E6),"P",IF(AND(IA$4>=$E6,IA$4<$F6),"T","")))
A7: 2 | B7: =Premissas!$B$6 -> 6 | C7: =1*Premissas!$B$8 -> 12.121212 | D7: =C7+Premissas!$B$9 -> 60.121212 | E7: =C7+Premissas!$B$11 -> 66.121212 | F7: =E7+Premissas!$B$8 -> 78.242424 | G7: =Premissas!$B$11 -> 54 | H7: =Premissas!$B$12 -> 3 | I7: PLANEJADA | J7: Slot serial; criação imutável. | K7: =IF(AND(K$4>=$C7,K$4<$D7),"R",IF(AND(K$4>=$D7,K$4<$E7),"P",IF(AND(K$4>=$E7,K$4<$F7),"T",""))) | L7: =IF(AND(L$4>=$C7,L$4<$D7),"R",IF(AND(L$4>=$D7,L$4<$E7),"P",IF(AND(L$4>=$E7,L$4<$F7),"T",""))) | M7: =IF(AND(M$4>=$C7,M$4<$D7),"R",IF(AND(M$4>=$D7,M$4<$E7),"P",IF(AND(M$4>=$E7,M$4<$F7),"T",""))) | N7: =IF(AND(N$4>=$C7,N$4<$D7),"R",IF(AND(N$4>=$D7,N$4<$E7),"P",IF(AND(N$4>=$E7,N$4<$F7),"T",""))) | O7: =IF(AND(O$4>=$C7,O$4<$D7),"R",IF(AND(O$4>=$D7,O$4<$E7),"P",IF(AND(O$4>=$E7,O$4<$F7),"T",""))) | P7: =IF(AND(P$4>=$C7,P$4<$D7),"R",IF(AND(P$4>=$D7,P$4<$E7),"P",IF(AND(P$4>=$E7,P$4<$F7),"T",""))) -> R | Q7: =IF(AND(Q$4>=$C7,Q$4<$D7),"R",IF(AND(Q$4>=$D7,Q$4<$E7),"P",IF(AND(Q$4>=$E7,Q$4<$F7),"T",""))) -> R | R7: =IF(AND(R$4>=$C7,R$4<$D7),"R",IF(AND(R$4>=$D7,R$4<$E7),"P",IF(AND(R$4>=$E7,R$4<$F7),"T",""))) -> R | ... IA7: =IF(AND(IA$4>=$C7,IA$4<$D7),"R",IF(AND(IA$4>=$D7,IA$4<$E7),"P",IF(AND(IA$4>=$E7,IA$4<$F7),"T","")))
A8: 3 | B8: =Premissas!$B$6 -> 6 | C8: =2*Premissas!$B$8 -> 24.242424 | D8: =C8+Premissas!$B$9 -> 72.242424 | E8: =C8+Premissas!$B$11 -> 78.242424 | F8: =E8+Premissas!$B$8 -> 90.363636 | G8: =Premissas!$B$11 -> 54 | H8: =Premissas!$B$12 -> 3 | I8: PLANEJADA | J8: Slot serial; criação imutável. | K8: =IF(AND(K$4>=$C8,K$4<$D8),"R",IF(AND(K$4>=$D8,K$4<$E8),"P",IF(AND(K$4>=$E8,K$4<$F8),"T",""))) | L8: =IF(AND(L$4>=$C8,L$4<$D8),"R",IF(AND(L$4>=$D8,L$4<$E8),"P",IF(AND(L$4>=$E8,L$4<$F8),"T",""))) | M8: =IF(AND(M$4>=$C8,M$4<$D8),"R",IF(AND(M$4>=$D8,M$4<$E8),"P",IF(AND(M$4>=$E8,M$4<$F8),"T",""))) | N8: =IF(AND(N$4>=$C8,N$4<$D8),"R",IF(AND(N$4>=$D8,N$4<$E8),"P",IF(AND(N$4>=$E8,N$4<$F8),"T",""))) | O8: =IF(AND(O$4>=$C8,O$4<$D8),"R",IF(AND(O$4>=$D8,O$4<$E8),"P",IF(AND(O$4>=$E8,O$4<$F8),"T",""))) | P8: =IF(AND(P$4>=$C8,P$4<$D8),"R",IF(AND(P$4>=$D8,P$4<$E8),"P",IF(AND(P$4>=$E8,P$4<$F8),"T",""))) | Q8: =IF(AND(Q$4>=$C8,Q$4<$D8),"R",IF(AND(Q$4>=$D8,Q$4<$E8),"P",IF(AND(Q$4>=$E8,Q$4<$F8),"T",""))) | R8: =IF(AND(R$4>=$C8,R$4<$D8),"R",IF(AND(R$4>=$D8,R$4<$E8),"P",IF(AND(R$4>=$E8,R$4<$F8),"T",""))) | ... IA8: =IF(AND(IA$4>=$C8,IA$4<$D8),"R",IF(AND(IA$4>=$D8,IA$4<$E8),"P",IF(AND(IA$4>=$E8,IA$4<$F8),"T","")))
A9: 4 | B9: =Premissas!$B$6 -> 6 | C9: =3*Premissas!$B$8 -> 36.363636 | D9: =C9+Premissas!$B$9 -> 84.363636 | E9: =C9+Premissas!$B$11 -> 90.363636 | F9: =E9+Premissas!$B$8 -> 102.48485 | G9: =Premissas!$B$11 -> 54 | H9: =Premissas!$B$12 -> 3 | I9: PLANEJADA | J9: Slot serial; criação imutável. | K9: =IF(AND(K$4>=$C9,K$4<$D9),"R",IF(AND(K$4>=$D9,K$4<$E9),"P",IF(AND(K$4>=$E9,K$4<$F9),"T",""))) | L9: =IF(AND(L$4>=$C9,L$4<$D9),"R",IF(AND(L$4>=$D9,L$4<$E9),"P",IF(AND(L$4>=$E9,L$4<$F9),"T",""))) | M9: =IF(AND(M$4>=$C9,M$4<$D9),"R",IF(AND(M$4>=$D9,M$4<$E9),"P",IF(AND(M$4>=$E9,M$4<$F9),"T",""))) | N9: =IF(AND(N$4>=$C9,N$4<$D9),"R",IF(AND(N$4>=$D9,N$4<$E9),"P",IF(AND(N$4>=$E9,N$4<$F9),"T",""))) | O9: =IF(AND(O$4>=$C9,O$4<$D9),"R",IF(AND(O$4>=$D9,O$4<$E9),"P",IF(AND(O$4>=$E9,O$4<$F9),"T",""))) | P9: =IF(AND(P$4>=$C9,P$4<$D9),"R",IF(AND(P$4>=$D9,P$4<$E9),"P",IF(AND(P$4>=$E9,P$4<$F9),"T",""))) | Q9: =IF(AND(Q$4>=$C9,Q$4<$D9),"R",IF(AND(Q$4>=$D9,Q$4<$E9),"P",IF(AND(Q$4>=$E9,Q$4<$F9),"T",""))) | R9: =IF(AND(R$4>=$C9,R$4<$D9),"R",IF(AND(R$4>=$D9,R$4<$E9),"P",IF(AND(R$4>=$E9,R$4<$F9),"T",""))) | ... IA9: =IF(AND(IA$4>=$C9,IA$4<$D9),"R",IF(AND(IA$4>=$D9,IA$4<$E9),"P",IF(AND(IA$4>=$E9,IA$4<$F9),"T","")))
A10: 5 | B10: =Premissas!$B$6 -> 6 | C10: =4*Premissas!$B$8 -> 48.484848 | D10: =C10+Premissas!$B$9 -> 96.484848 | E10: =C10+Premissas!$B$11 -> 102.48485 | F10: =E10+Premissas!$B$8 -> 114.60606 | G10: =Premissas!$B$11 -> 54 | H10: =Premissas!$B$12 -> 3 | I10: PLANEJADA | J10: Slot serial; criação imutável. | K10: =IF(AND(K$4>=$C10,K$4<$D10),"R",IF(AND(K$4>=$D10,K$4<$E10),"P",IF(AND(K$4>=$E10,K$4<$F10),"T",""))) | L10: =IF(AND(L$4>=$C10,L$4<$D10),"R",IF(AND(L$4>=$D10,L$4<$E10),"P",IF(AND(L$4>=$E10,L$4<$F10),"T",""))) | M10: =IF(AND(M$4>=$C10,M$4<$D10),"R",IF(AND(M$4>=$D10,M$4<$E10),"P",IF(AND(M$4>=$E10,M$4<$F10),"T",""))) | N10: =IF(AND(N$4>=$C10,N$4<$D10),"R",IF(AND(N$4>=$D10,N$4<$E10),"P",IF(AND(N$4>=$E10,N$4<$F10),"T",""))) | O10: =IF(AND(O$4>=$C10,O$4<$D10),"R",IF(AND(O$4>=$D10,O$4<$E10),"P",IF(AND(O$4>=$E10,O$4<$F10),"T",""))) | P10: =IF(AND(P$4>=$C10,P$4<$D10),"R",IF(AND(P$4>=$D10,P$4<$E10),"P",IF(AND(P$4>=$E10,P$4<$F10),"T",""))) | Q10: =IF(AND(Q$4>=$C10,Q$4<$D10),"R",IF(AND(Q$4>=$D10,Q$4<$E10),"P",IF(AND(Q$4>=$E10,Q$4<$F10),"T",""))) | R10: =IF(AND(R$4>=$C10,R$4<$D10),"R",IF(AND(R$4>=$D10,R$4<$E10),"P",IF(AND(R$4>=$E10,R$4<$F10),"T",""))) | ... IA10: =IF(AND(IA$4>=$C10,IA$4<$D10),"R",IF(AND(IA$4>=$D10,IA$4<$E10),"P",IF(AND(IA$4>=$E10,IA$4<$F10),"T","")))
A11: 6 | B11: =Premissas!$B$6 -> 6 | C11: =5*Premissas!$B$8 -> 60.606061 | D11: =C11+Premissas!$B$9 -> 108.60606 | E11: =C11+Premissas!$B$11 -> 114.60606 | F11: =E11+Premissas!$B$8 -> 126.72727 | G11: =Premissas!$B$11 -> 54 | H11: =Premissas!$B$12 -> 3 | I11: PLANEJADA | J11: Slot serial; criação imutável. | K11: =IF(AND(K$4>=$C11,K$4<$D11),"R",IF(AND(K$4>=$D11,K$4<$E11),"P",IF(AND(K$4>=$E11,K$4<$F11),"T",""))) | L11: =IF(AND(L$4>=$C11,L$4<$D11),"R",IF(AND(L$4>=$D11,L$4<$E11),"P",IF(AND(L$4>=$E11,L$4<$F11),"T",""))) | M11: =IF(AND(M$4>=$C11,M$4<$D11),"R",IF(AND(M$4>=$D11,M$4<$E11),"P",IF(AND(M$4>=$E11,M$4<$F11),"T",""))) | N11: =IF(AND(N$4>=$C11,N$4<$D11),"R",IF(AND(N$4>=$D11,N$4<$E11),"P",IF(AND(N$4>=$E11,N$4<$F11),"T",""))) | O11: =IF(AND(O$4>=$C11,O$4<$D11),"R",IF(AND(O$4>=$D11,O$4<$E11),"P",IF(AND(O$4>=$E11,O$4<$F11),"T",""))) | P11: =IF(AND(P$4>=$C11,P$4<$D11),"R",IF(AND(P$4>=$D11,P$4<$E11),"P",IF(AND(P$4>=$E11,P$4<$F11),"T",""))) | Q11: =IF(AND(Q$4>=$C11,Q$4<$D11),"R",IF(AND(Q$4>=$D11,Q$4<$E11),"P",IF(AND(Q$4>=$E11,Q$4<$F11),"T",""))) | R11: =IF(AND(R$4>=$C11,R$4<$D11),"R",IF(AND(R$4>=$D11,R$4<$E11),"P",IF(AND(R$4>=$E11,R$4<$F11),"T",""))) | ... IA11: =IF(AND(IA$4>=$C11,IA$4<$D11),"R",IF(AND(IA$4>=$D11,IA$4<$E11),"P",IF(AND(IA$4>=$E11,IA$4<$F11),"T","")))
A12: 7 | B12: =Premissas!$B$6 -> 6 | C12: =6*Premissas!$B$8 -> 72.727273 | D12: =C12+Premissas!$B$9 -> 120.72727 | E12: =C12+Premissas!$B$11 -> 126.72727 | F12: =E12+Premissas!$B$8 -> 138.84848 | G12: =Premissas!$B$11 -> 54 | H12: =Premissas!$B$12 -> 3 | I12: PLANEJADA | J12: Slot serial; criação imutável. | K12: =IF(AND(K$4>=$C12,K$4<$D12),"R",IF(AND(K$4>=$D12,K$4<$E12),"P",IF(AND(K$4>=$E12,K$4<$F12),"T",""))) | L12: =IF(AND(L$4>=$C12,L$4<$D12),"R",IF(AND(L$4>=$D12,L$4<$E12),"P",IF(AND(L$4>=$E12,L$4<$F12),"T",""))) | M12: =IF(AND(M$4>=$C12,M$4<$D12),"R",IF(AND(M$4>=$D12,M$4<$E12),"P",IF(AND(M$4>=$E12,M$4<$F12),"T",""))) | N12: =IF(AND(N$4>=$C12,N$4<$D12),"R",IF(AND(N$4>=$D12,N$4<$E12),"P",IF(AND(N$4>=$E12,N$4<$F12),"T",""))) | O12: =IF(AND(O$4>=$C12,O$4<$D12),"R",IF(AND(O$4>=$D12,O$4<$E12),"P",IF(AND(O$4>=$E12,O$4<$F12),"T",""))) | P12: =IF(AND(P$4>=$C12,P$4<$D12),"R",IF(AND(P$4>=$D12,P$4<$E12),"P",IF(AND(P$4>=$E12,P$4<$F12),"T",""))) | Q12: =IF(AND(Q$4>=$C12,Q$4<$D12),"R",IF(AND(Q$4>=$D12,Q$4<$E12),"P",IF(AND(Q$4>=$E12,Q$4<$F12),"T",""))) | R12: =IF(AND(R$4>=$C12,R$4<$D12),"R",IF(AND(R$4>=$D12,R$4<$E12),"P",IF(AND(R$4>=$E12,R$4<$F12),"T",""))) | ... IA12: =IF(AND(IA$4>=$C12,IA$4<$D12),"R",IF(AND(IA$4>=$D12,IA$4<$E12),"P",IF(AND(IA$4>=$E12,IA$4<$F12),"T","")))
A13: 8 | B13: =Premissas!$B$6 -> 6 | C13: =7*Premissas!$B$8 -> 84.848485 | D13: =C13+Premissas!$B$9 -> 132.84848 | E13: =C13+Premissas!$B$11 -> 138.84848 | F13: =E13+Premissas!$B$8 -> 150.9697 | G13: =Premissas!$B$11 -> 54 | H13: =Premissas!$B$12 -> 3 | I13: PLANEJADA | J13: Slot serial; criação imutável. | K13: =IF(AND(K$4>=$C13,K$4<$D13),"R",IF(AND(K$4>=$D13,K$4<$E13),"P",IF(AND(K$4>=$E13,K$4<$F13),"T",""))) | L13: =IF(AND(L$4>=$C13,L$4<$D13),"R",IF(AND(L$4>=$D13,L$4<$E13),"P",IF(AND(L$4>=$E13,L$4<$F13),"T",""))) | M13: =IF(AND(M$4>=$C13,M$4<$D13),"R",IF(AND(M$4>=$D13,M$4<$E13),"P",IF(AND(M$4>=$E13,M$4<$F13),"T",""))) | N13: =IF(AND(N$4>=$C13,N$4<$D13),"R",IF(AND(N$4>=$D13,N$4<$E13),"P",IF(AND(N$4>=$E13,N$4<$F13),"T",""))) | O13: =IF(AND(O$4>=$C13,O$4<$D13),"R",IF(AND(O$4>=$D13,O$4<$E13),"P",IF(AND(O$4>=$E13,O$4<$F13),"T",""))) | P13: =IF(AND(P$4>=$C13,P$4<$D13),"R",IF(AND(P$4>=$D13,P$4<$E13),"P",IF(AND(P$4>=$E13,P$4<$F13),"T",""))) | Q13: =IF(AND(Q$4>=$C13,Q$4<$D13),"R",IF(AND(Q$4>=$D13,Q$4<$E13),"P",IF(AND(Q$4>=$E13,Q$4<$F13),"T",""))) | R13: =IF(AND(R$4>=$C13,R$4<$D13),"R",IF(AND(R$4>=$D13,R$4<$E13),"P",IF(AND(R$4>=$E13,R$4<$F13),"T",""))) | ... IA13: =IF(AND(IA$4>=$C13,IA$4<$D13),"R",IF(AND(IA$4>=$D13,IA$4<$E13),"P",IF(AND(IA$4>=$E13,IA$4<$F13),"T","")))
A14: 9 | B14: =Premissas!$B$6 -> 6 | C14: =8*Premissas!$B$8 -> 96.969697 | D14: =C14+Premissas!$B$9 -> 144.9697 | E14: =C14+Premissas!$B$11 -> 150.9697 | F14: =E14+Premissas!$B$8 -> 163.09091 | G14: =Premissas!$B$11 -> 54 | H14: =Premissas!$B$12 -> 3 | I14: PLANEJADA | J14: Slot serial; criação imutável. | K14: =IF(AND(K$4>=$C14,K$4<$D14),"R",IF(AND(K$4>=$D14,K$4<$E14),"P",IF(AND(K$4>=$E14,K$4<$F14),"T",""))) | L14: =IF(AND(L$4>=$C14,L$4<$D14),"R",IF(AND(L$4>=$D14,L$4<$E14),"P",IF(AND(L$4>=$E14,L$4<$F14),"T",""))) | M14: =IF(AND(M$4>=$C14,M$4<$D14),"R",IF(AND(M$4>=$D14,M$4<$E14),"P",IF(AND(M$4>=$E14,M$4<$F14),"T",""))) | N14: =IF(AND(N$4>=$C14,N$4<$D14),"R",IF(AND(N$4>=$D14,N$4<$E14),"P",IF(AND(N$4>=$E14,N$4<$F14),"T",""))) | O14: =IF(AND(O$4>=$C14,O$4<$D14),"R",IF(AND(O$4>=$D14,O$4<$E14),"P",IF(AND(O$4>=$E14,O$4<$F14),"T",""))) | P14: =IF(AND(P$4>=$C14,P$4<$D14),"R",IF(AND(P$4>=$D14,P$4<$E14),"P",IF(AND(P$4>=$E14,P$4<$F14),"T",""))) | Q14: =IF(AND(Q$4>=$C14,Q$4<$D14),"R",IF(AND(Q$4>=$D14,Q$4<$E14),"P",IF(AND(Q$4>=$E14,Q$4<$F14),"T",""))) | R14: =IF(AND(R$4>=$C14,R$4<$D14),"R",IF(AND(R$4>=$D14,R$4<$E14),"P",IF(AND(R$4>=$E14,R$4<$F14),"T",""))) | ... IA14: =IF(AND(IA$4>=$C14,IA$4<$D14),"R",IF(AND(IA$4>=$D14,IA$4<$E14),"P",IF(AND(IA$4>=$E14,IA$4<$F14),"T","")))
A15: 10 | B15: =Premissas!$B$6 -> 6 | C15: =9*Premissas!$B$8 -> 109.09091 | D15: =C15+Premissas!$B$9 -> 157.09091 | E15: =C15+Premissas!$B$11 -> 163.09091 | F15: =E15+Premissas!$B$8 -> 175.21212 | G15: =Premissas!$B$11 -> 54 | H15: =Premissas!$B$12 -> 3 | I15: PLANEJADA | J15: Slot serial; criação imutável. | K15: =IF(AND(K$4>=$C15,K$4<$D15),"R",IF(AND(K$4>=$D15,K$4<$E15),"P",IF(AND(K$4>=$E15,K$4<$F15),"T",""))) | L15: =IF(AND(L$4>=$C15,L$4<$D15),"R",IF(AND(L$4>=$D15,L$4<$E15),"P",IF(AND(L$4>=$E15,L$4<$F15),"T",""))) | M15: =IF(AND(M$4>=$C15,M$4<$D15),"R",IF(AND(M$4>=$D15,M$4<$E15),"P",IF(AND(M$4>=$E15,M$4<$F15),"T",""))) | N15: =IF(AND(N$4>=$C15,N$4<$D15),"R",IF(AND(N$4>=$D15,N$4<$E15),"P",IF(AND(N$4>=$E15,N$4<$F15),"T",""))) | O15: =IF(AND(O$4>=$C15,O$4<$D15),"R",IF(AND(O$4>=$D15,O$4<$E15),"P",IF(AND(O$4>=$E15,O$4<$F15),"T",""))) | P15: =IF(AND(P$4>=$C15,P$4<$D15),"R",IF(AND(P$4>=$D15,P$4<$E15),"P",IF(AND(P$4>=$E15,P$4<$F15),"T",""))) | Q15: =IF(AND(Q$4>=$C15,Q$4<$D15),"R",IF(AND(Q$4>=$D15,Q$4<$E15),"P",IF(AND(Q$4>=$E15,Q$4<$F15),"T",""))) | R15: =IF(AND(R$4>=$C15,R$4<$D15),"R",IF(AND(R$4>=$D15,R$4<$E15),"P",IF(AND(R$4>=$E15,R$4<$F15),"T",""))) | ... IA15: =IF(AND(IA$4>=$C15,IA$4<$D15),"R",IF(AND(IA$4>=$D15,IA$4<$E15),"P",IF(AND(IA$4>=$E15,IA$4<$F15),"T","")))
A16: 11 | B16: =Premissas!$B$6 -> 6 | C16: =10*Premissas!$B$8 -> 121.21212 | D16: =C16+Premissas!$B$9 -> 169.21212 | E16: =C16+Premissas!$B$11 -> 175.21212 | F16: =E16+Premissas!$B$8 -> 187.33333 | G16: =Premissas!$B$11 -> 54 | H16: =Premissas!$B$12 -> 3 | I16: PLANEJADA | J16: Slot serial; criação imutável. | K16: =IF(AND(K$4>=$C16,K$4<$D16),"R",IF(AND(K$4>=$D16,K$4<$E16),"P",IF(AND(K$4>=$E16,K$4<$F16),"T",""))) | L16: =IF(AND(L$4>=$C16,L$4<$D16),"R",IF(AND(L$4>=$D16,L$4<$E16),"P",IF(AND(L$4>=$E16,L$4<$F16),"T",""))) | M16: =IF(AND(M$4>=$C16,M$4<$D16),"R",IF(AND(M$4>=$D16,M$4<$E16),"P",IF(AND(M$4>=$E16,M$4<$F16),"T",""))) | N16: =IF(AND(N$4>=$C16,N$4<$D16),"R",IF(AND(N$4>=$D16,N$4<$E16),"P",IF(AND(N$4>=$E16,N$4<$F16),"T",""))) | O16: =IF(AND(O$4>=$C16,O$4<$D16),"R",IF(AND(O$4>=$D16,O$4<$E16),"P",IF(AND(O$4>=$E16,O$4<$F16),"T",""))) | P16: =IF(AND(P$4>=$C16,P$4<$D16),"R",IF(AND(P$4>=$D16,P$4<$E16),"P",IF(AND(P$4>=$E16,P$4<$F16),"T",""))) | Q16: =IF(AND(Q$4>=$C16,Q$4<$D16),"R",IF(AND(Q$4>=$D16,Q$4<$E16),"P",IF(AND(Q$4>=$E16,Q$4<$F16),"T",""))) | R16: =IF(AND(R$4>=$C16,R$4<$D16),"R",IF(AND(R$4>=$D16,R$4<$E16),"P",IF(AND(R$4>=$E16,R$4<$F16),"T",""))) | ... IA16: =IF(AND(IA$4>=$C16,IA$4<$D16),"R",IF(AND(IA$4>=$D16,IA$4<$E16),"P",IF(AND(IA$4>=$E16,IA$4<$F16),"T","")))
A17: 12 | B17: =Premissas!$B$6 -> 6 | C17: =11*Premissas!$B$8 -> 133.33333 | D17: =C17+Premissas!$B$9 -> 181.33333 | E17: =C17+Premissas!$B$11 -> 187.33333 | F17: =E17+Premissas!$B$8 -> 199.45455 | G17: =Premissas!$B$11 -> 54 | H17: =Premissas!$B$12 -> 3 | I17: PLANEJADA | J17: Slot serial; criação imutável. | K17: =IF(AND(K$4>=$C17,K$4<$D17),"R",IF(AND(K$4>=$D17,K$4<$E17),"P",IF(AND(K$4>=$E17,K$4<$F17),"T",""))) | L17: =IF(AND(L$4>=$C17,L$4<$D17),"R",IF(AND(L$4>=$D17,L$4<$E17),"P",IF(AND(L$4>=$E17,L$4<$F17),"T",""))) | M17: =IF(AND(M$4>=$C17,M$4<$D17),"R",IF(AND(M$4>=$D17,M$4<$E17),"P",IF(AND(M$4>=$E17,M$4<$F17),"T",""))) | N17: =IF(AND(N$4>=$C17,N$4<$D17),"R",IF(AND(N$4>=$D17,N$4<$E17),"P",IF(AND(N$4>=$E17,N$4<$F17),"T",""))) | O17: =IF(AND(O$4>=$C17,O$4<$D17),"R",IF(AND(O$4>=$D17,O$4<$E17),"P",IF(AND(O$4>=$E17,O$4<$F17),"T",""))) | P17: =IF(AND(P$4>=$C17,P$4<$D17),"R",IF(AND(P$4>=$D17,P$4<$E17),"P",IF(AND(P$4>=$E17,P$4<$F17),"T",""))) | Q17: =IF(AND(Q$4>=$C17,Q$4<$D17),"R",IF(AND(Q$4>=$D17,Q$4<$E17),"P",IF(AND(Q$4>=$E17,Q$4<$F17),"T",""))) | R17: =IF(AND(R$4>=$C17,R$4<$D17),"R",IF(AND(R$4>=$D17,R$4<$E17),"P",IF(AND(R$4>=$E17,R$4<$F17),"T",""))) | ... IA17: =IF(AND(IA$4>=$C17,IA$4<$D17),"R",IF(AND(IA$4>=$D17,IA$4<$E17),"P",IF(AND(IA$4>=$E17,IA$4<$F17),"T","")))
A18: 13 | B18: =Premissas!$B$6 -> 6 | C18: =12*Premissas!$B$8 -> 145.45455 | D18: =C18+Premissas!$B$9 -> 193.45455 | E18: =C18+Premissas!$B$11 -> 199.45455 | F18: =E18+Premissas!$B$8 -> 211.57576 | G18: =Premissas!$B$11 -> 54 | H18: =Premissas!$B$12 -> 3 | I18: PLANEJADA | J18: Slot serial; criação imutável. | K18: =IF(AND(K$4>=$C18,K$4<$D18),"R",IF(AND(K$4>=$D18,K$4<$E18),"P",IF(AND(K$4>=$E18,K$4<$F18),"T",""))) | L18: =IF(AND(L$4>=$C18,L$4<$D18),"R",IF(AND(L$4>=$D18,L$4<$E18),"P",IF(AND(L$4>=$E18,L$4<$F18),"T",""))) | M18: =IF(AND(M$4>=$C18,M$4<$D18),"R",IF(AND(M$4>=$D18,M$4<$E18),"P",IF(AND(M$4>=$E18,M$4<$F18),"T",""))) | N18: =IF(AND(N$4>=$C18,N$4<$D18),"R",IF(AND(N$4>=$D18,N$4<$E18),"P",IF(AND(N$4>=$E18,N$4<$F18),"T",""))) | O18: =IF(AND(O$4>=$C18,O$4<$D18),"R",IF(AND(O$4>=$D18,O$4<$E18),"P",IF(AND(O$4>=$E18,O$4<$F18),"T",""))) | P18: =IF(AND(P$4>=$C18,P$4<$D18),"R",IF(AND(P$4>=$D18,P$4<$E18),"P",IF(AND(P$4>=$E18,P$4<$F18),"T",""))) | Q18: =IF(AND(Q$4>=$C18,Q$4<$D18),"R",IF(AND(Q$4>=$D18,Q$4<$E18),"P",IF(AND(Q$4>=$E18,Q$4<$F18),"T",""))) | R18: =IF(AND(R$4>=$C18,R$4<$D18),"R",IF(AND(R$4>=$D18,R$4<$E18),"P",IF(AND(R$4>=$E18,R$4<$F18),"T",""))) | ... IA18: =IF(AND(IA$4>=$C18,IA$4<$D18),"R",IF(AND(IA$4>=$D18,IA$4<$E18),"P",IF(AND(IA$4>=$E18,IA$4<$F18),"T","")))
A19: 14 | B19: =Premissas!$B$6 -> 6 | C19: =13*Premissas!$B$8 -> 157.57576 | D19: =C19+Premissas!$B$9 -> 205.57576 | E19: =C19+Premissas!$B$11 -> 211.57576 | F19: =E19+Premissas!$B$8 -> 223.69697 | G19: =Premissas!$B$11 -> 54 | H19: =Premissas!$B$12 -> 3 | I19: PLANEJADA | J19: Slot serial; criação imutável. | K19: =IF(AND(K$4>=$C19,K$4<$D19),"R",IF(AND(K$4>=$D19,K$4<$E19),"P",IF(AND(K$4>=$E19,K$4<$F19),"T",""))) | L19: =IF(AND(L$4>=$C19,L$4<$D19),"R",IF(AND(L$4>=$D19,L$4<$E19),"P",IF(AND(L$4>=$E19,L$4<$F19),"T",""))) | M19: =IF(AND(M$4>=$C19,M$4<$D19),"R",IF(AND(M$4>=$D19,M$4<$E19),"P",IF(AND(M$4>=$E19,M$4<$F19),"T",""))) | N19: =IF(AND(N$4>=$C19,N$4<$D19),"R",IF(AND(N$4>=$D19,N$4<$E19),"P",IF(AND(N$4>=$E19,N$4<$F19),"T",""))) | O19: =IF(AND(O$4>=$C19,O$4<$D19),"R",IF(AND(O$4>=$D19,O$4<$E19),"P",IF(AND(O$4>=$E19,O$4<$F19),"T",""))) | P19: =IF(AND(P$4>=$C19,P$4<$D19),"R",IF(AND(P$4>=$D19,P$4<$E19),"P",IF(AND(P$4>=$E19,P$4<$F19),"T",""))) | Q19: =IF(AND(Q$4>=$C19,Q$4<$D19),"R",IF(AND(Q$4>=$D19,Q$4<$E19),"P",IF(AND(Q$4>=$E19,Q$4<$F19),"T",""))) | R19: =IF(AND(R$4>=$C19,R$4<$D19),"R",IF(AND(R$4>=$D19,R$4<$E19),"P",IF(AND(R$4>=$E19,R$4<$F19),"T",""))) | ... IA19: =IF(AND(IA$4>=$C19,IA$4<$D19),"R",IF(AND(IA$4>=$D19,IA$4<$E19),"P",IF(AND(IA$4>=$E19,IA$4<$F19),"T","")))
A20: 15 | B20: =Premissas!$B$6 -> 6 | C20: =14*Premissas!$B$8 -> 169.69697 | D20: =C20+Premissas!$B$9 -> 217.69697 | E20: =C20+Premissas!$B$11 -> 223.69697 | F20: =E20+Premissas!$B$8 -> 235.81818 | G20: =Premissas!$B$11 -> 54 | H20: =Premissas!$B$12 -> 3 | I20: PLANEJADA | J20: Slot serial; criação imutável. | K20: =IF(AND(K$4>=$C20,K$4<$D20),"R",IF(AND(K$4>=$D20,K$4<$E20),"P",IF(AND(K$4>=$E20,K$4<$F20),"T",""))) | L20: =IF(AND(L$4>=$C20,L$4<$D20),"R",IF(AND(L$4>=$D20,L$4<$E20),"P",IF(AND(L$4>=$E20,L$4<$F20),"T",""))) | M20: =IF(AND(M$4>=$C20,M$4<$D20),"R",IF(AND(M$4>=$D20,M$4<$E20),"P",IF(AND(M$4>=$E20,M$4<$F20),"T",""))) | N20: =IF(AND(N$4>=$C20,N$4<$D20),"R",IF(AND(N$4>=$D20,N$4<$E20),"P",IF(AND(N$4>=$E20,N$4<$F20),"T",""))) | O20: =IF(AND(O$4>=$C20,O$4<$D20),"R",IF(AND(O$4>=$D20,O$4<$E20),"P",IF(AND(O$4>=$E20,O$4<$F20),"T",""))) | P20: =IF(AND(P$4>=$C20,P$4<$D20),"R",IF(AND(P$4>=$D20,P$4<$E20),"P",IF(AND(P$4>=$E20,P$4<$F20),"T",""))) | Q20: =IF(AND(Q$4>=$C20,Q$4<$D20),"R",IF(AND(Q$4>=$D20,Q$4<$E20),"P",IF(AND(Q$4>=$E20,Q$4<$F20),"T",""))) | R20: =IF(AND(R$4>=$C20,R$4<$D20),"R",IF(AND(R$4>=$D20,R$4<$E20),"P",IF(AND(R$4>=$E20,R$4<$F20),"T",""))) | ... IA20: =IF(AND(IA$4>=$C20,IA$4<$D20),"R",IF(AND(IA$4>=$D20,IA$4<$E20),"P",IF(AND(IA$4>=$E20,IA$4<$F20),"T","")))
A21: 16 | B21: =Premissas!$B$6 -> 6 | C21: =15*Premissas!$B$8 -> 181.81818 | D21: =C21+Premissas!$B$9 -> 229.81818 | E21: =C21+Premissas!$B$11 -> 235.81818 | F21: =E21+Premissas!$B$8 -> 247.93939 | G21: =Premissas!$B$11 -> 54 | H21: =Premissas!$B$12 -> 3 | I21: PLANEJADA | J21: Slot serial; criação imutável. | K21: =IF(AND(K$4>=$C21,K$4<$D21),"R",IF(AND(K$4>=$D21,K$4<$E21),"P",IF(AND(K$4>=$E21,K$4<$F21),"T",""))) | L21: =IF(AND(L$4>=$C21,L$4<$D21),"R",IF(AND(L$4>=$D21,L$4<$E21),"P",IF(AND(L$4>=$E21,L$4<$F21),"T",""))) | M21: =IF(AND(M$4>=$C21,M$4<$D21),"R",IF(AND(M$4>=$D21,M$4<$E21),"P",IF(AND(M$4>=$E21,M$4<$F21),"T",""))) | N21: =IF(AND(N$4>=$C21,N$4<$D21),"R",IF(AND(N$4>=$D21,N$4<$E21),"P",IF(AND(N$4>=$E21,N$4<$F21),"T",""))) | O21: =IF(AND(O$4>=$C21,O$4<$D21),"R",IF(AND(O$4>=$D21,O$4<$E21),"P",IF(AND(O$4>=$E21,O$4<$F21),"T",""))) | P21: =IF(AND(P$4>=$C21,P$4<$D21),"R",IF(AND(P$4>=$D21,P$4<$E21),"P",IF(AND(P$4>=$E21,P$4<$F21),"T",""))) | Q21: =IF(AND(Q$4>=$C21,Q$4<$D21),"R",IF(AND(Q$4>=$D21,Q$4<$E21),"P",IF(AND(Q$4>=$E21,Q$4<$F21),"T",""))) | R21: =IF(AND(R$4>=$C21,R$4<$D21),"R",IF(AND(R$4>=$D21,R$4<$E21),"P",IF(AND(R$4>=$E21,R$4<$F21),"T",""))) | ... IA21: =IF(AND(IA$4>=$C21,IA$4<$D21),"R",IF(AND(IA$4>=$D21,IA$4<$E21),"P",IF(AND(IA$4>=$E21,IA$4<$F21),"T","")))
A22: 17 | B22: =Premissas!$B$6 -> 6 | C22: =16*Premissas!$B$8 -> 193.93939 | D22: =C22+Premissas!$B$9 -> 241.93939 | E22: =C22+Premissas!$B$11 -> 247.93939 | F22: =E22+Premissas!$B$8 -> 260.06061 | G22: =Premissas!$B$11 -> 54 | H22: =Premissas!$B$12 -> 3 | I22: PLANEJADA | J22: Slot serial; criação imutável. | K22: =IF(AND(K$4>=$C22,K$4<$D22),"R",IF(AND(K$4>=$D22,K$4<$E22),"P",IF(AND(K$4>=$E22,K$4<$F22),"T",""))) | L22: =IF(AND(L$4>=$C22,L$4<$D22),"R",IF(AND(L$4>=$D22,L$4<$E22),"P",IF(AND(L$4>=$E22,L$4<$F22),"T",""))) | M22: =IF(AND(M$4>=$C22,M$4<$D22),"R",IF(AND(M$4>=$D22,M$4<$E22),"P",IF(AND(M$4>=$E22,M$4<$F22),"T",""))) | N22: =IF(AND(N$4>=$C22,N$4<$D22),"R",IF(AND(N$4>=$D22,N$4<$E22),"P",IF(AND(N$4>=$E22,N$4<$F22),"T",""))) | O22: =IF(AND(O$4>=$C22,O$4<$D22),"R",IF(AND(O$4>=$D22,O$4<$E22),"P",IF(AND(O$4>=$E22,O$4<$F22),"T",""))) | P22: =IF(AND(P$4>=$C22,P$4<$D22),"R",IF(AND(P$4>=$D22,P$4<$E22),"P",IF(AND(P$4>=$E22,P$4<$F22),"T",""))) | Q22: =IF(AND(Q$4>=$C22,Q$4<$D22),"R",IF(AND(Q$4>=$D22,Q$4<$E22),"P",IF(AND(Q$4>=$E22,Q$4<$F22),"T",""))) | R22: =IF(AND(R$4>=$C22,R$4<$D22),"R",IF(AND(R$4>=$D22,R$4<$E22),"P",IF(AND(R$4>=$E22,R$4<$F22),"T",""))) | ... IA22: =IF(AND(IA$4>=$C22,IA$4<$D22),"R",IF(AND(IA$4>=$D22,IA$4<$E22),"P",IF(AND(IA$4>=$E22,IA$4<$F22),"T","")))
A23: 18 | B23: =Premissas!$B$6 -> 6 | C23: =17*Premissas!$B$8 -> 206.06061 | D23: =C23+Premissas!$B$9 -> 254.06061 | E23: =C23+Premissas!$B$11 -> 260.06061 | F23: =E23+Premissas!$B$8 -> 272.18182 | G23: =Premissas!$B$11 -> 54 | H23: =Premissas!$B$12 -> 3 | I23: PLANEJADA | J23: Slot serial; criação imutável. | K23: =IF(AND(K$4>=$C23,K$4<$D23),"R",IF(AND(K$4>=$D23,K$4<$E23),"P",IF(AND(K$4>=$E23,K$4<$F23),"T",""))) | L23: =IF(AND(L$4>=$C23,L$4<$D23),"R",IF(AND(L$4>=$D23,L$4<$E23),"P",IF(AND(L$4>=$E23,L$4<$F23),"T",""))) | M23: =IF(AND(M$4>=$C23,M$4<$D23),"R",IF(AND(M$4>=$D23,M$4<$E23),"P",IF(AND(M$4>=$E23,M$4<$F23),"T",""))) | N23: =IF(AND(N$4>=$C23,N$4<$D23),"R",IF(AND(N$4>=$D23,N$4<$E23),"P",IF(AND(N$4>=$E23,N$4<$F23),"T",""))) | O23: =IF(AND(O$4>=$C23,O$4<$D23),"R",IF(AND(O$4>=$D23,O$4<$E23),"P",IF(AND(O$4>=$E23,O$4<$F23),"T",""))) | P23: =IF(AND(P$4>=$C23,P$4<$D23),"R",IF(AND(P$4>=$D23,P$4<$E23),"P",IF(AND(P$4>=$E23,P$4<$F23),"T",""))) | Q23: =IF(AND(Q$4>=$C23,Q$4<$D23),"R",IF(AND(Q$4>=$D23,Q$4<$E23),"P",IF(AND(Q$4>=$E23,Q$4<$F23),"T",""))) | R23: =IF(AND(R$4>=$C23,R$4<$D23),"R",IF(AND(R$4>=$D23,R$4<$E23),"P",IF(AND(R$4>=$E23,R$4<$F23),"T",""))) | ... IA23: =IF(AND(IA$4>=$C23,IA$4<$D23),"R",IF(AND(IA$4>=$D23,IA$4<$E23),"P",IF(AND(IA$4>=$E23,IA$4<$F23),"T","")))
A24: 19 | B24: =Premissas!$B$6 -> 6 | C24: =18*Premissas!$B$8 -> 218.18182 | D24: =C24+Premissas!$B$9 -> 266.18182 | E24: =C24+Premissas!$B$11 -> 272.18182 | F24: =E24+Premissas!$B$8 -> 284.30303 | G24: =Premissas!$B$11 -> 54 | H24: =Premissas!$B$12 -> 3 | I24: PLANEJADA | J24: Slot serial; criação imutável. | K24: =IF(AND(K$4>=$C24,K$4<$D24),"R",IF(AND(K$4>=$D24,K$4<$E24),"P",IF(AND(K$4>=$E24,K$4<$F24),"T",""))) | L24: =IF(AND(L$4>=$C24,L$4<$D24),"R",IF(AND(L$4>=$D24,L$4<$E24),"P",IF(AND(L$4>=$E24,L$4<$F24),"T",""))) | M24: =IF(AND(M$4>=$C24,M$4<$D24),"R",IF(AND(M$4>=$D24,M$4<$E24),"P",IF(AND(M$4>=$E24,M$4<$F24),"T",""))) | N24: =IF(AND(N$4>=$C24,N$4<$D24),"R",IF(AND(N$4>=$D24,N$4<$E24),"P",IF(AND(N$4>=$E24,N$4<$F24),"T",""))) | O24: =IF(AND(O$4>=$C24,O$4<$D24),"R",IF(AND(O$4>=$D24,O$4<$E24),"P",IF(AND(O$4>=$E24,O$4<$F24),"T",""))) | P24: =IF(AND(P$4>=$C24,P$4<$D24),"R",IF(AND(P$4>=$D24,P$4<$E24),"P",IF(AND(P$4>=$E24,P$4<$F24),"T",""))) | Q24: =IF(AND(Q$4>=$C24,Q$4<$D24),"R",IF(AND(Q$4>=$D24,Q$4<$E24),"P",IF(AND(Q$4>=$E24,Q$4<$F24),"T",""))) | R24: =IF(AND(R$4>=$C24,R$4<$D24),"R",IF(AND(R$4>=$D24,R$4<$E24),"P",IF(AND(R$4>=$E24,R$4<$F24),"T",""))) | ... IA24: =IF(AND(IA$4>=$C24,IA$4<$D24),"R",IF(AND(IA$4>=$D24,IA$4<$E24),"P",IF(AND(IA$4>=$E24,IA$4<$F24),"T","")))
A25: 20 | B25: =Premissas!$B$6 -> 6 | C25: =19*Premissas!$B$8 -> 230.30303 | D25: =C25+Premissas!$B$9 -> 278.30303 | E25: =C25+Premissas!$B$11 -> 284.30303 | F25: =E25+Premissas!$B$8 -> 296.42424 | G25: =Premissas!$B$11 -> 54 | H25: =Premissas!$B$12 -> 3 | I25: PLANEJADA | J25: Slot serial; criação imutável. | K25: =IF(AND(K$4>=$C25,K$4<$D25),"R",IF(AND(K$4>=$D25,K$4<$E25),"P",IF(AND(K$4>=$E25,K$4<$F25),"T",""))) | L25: =IF(AND(L$4>=$C25,L$4<$D25),"R",IF(AND(L$4>=$D25,L$4<$E25),"P",IF(AND(L$4>=$E25,L$4<$F25),"T",""))) | M25: =IF(AND(M$4>=$C25,M$4<$D25),"R",IF(AND(M$4>=$D25,M$4<$E25),"P",IF(AND(M$4>=$E25,M$4<$F25),"T",""))) | N25: =IF(AND(N$4>=$C25,N$4<$D25),"R",IF(AND(N$4>=$D25,N$4<$E25),"P",IF(AND(N$4>=$E25,N$4<$F25),"T",""))) | O25: =IF(AND(O$4>=$C25,O$4<$D25),"R",IF(AND(O$4>=$D25,O$4<$E25),"P",IF(AND(O$4>=$E25,O$4<$F25),"T",""))) | P25: =IF(AND(P$4>=$C25,P$4<$D25),"R",IF(AND(P$4>=$D25,P$4<$E25),"P",IF(AND(P$4>=$E25,P$4<$F25),"T",""))) | Q25: =IF(AND(Q$4>=$C25,Q$4<$D25),"R",IF(AND(Q$4>=$D25,Q$4<$E25),"P",IF(AND(Q$4>=$E25,Q$4<$F25),"T",""))) | R25: =IF(AND(R$4>=$C25,R$4<$D25),"R",IF(AND(R$4>=$D25,R$4<$E25),"P",IF(AND(R$4>=$E25,R$4<$F25),"T",""))) | ... IA25: =IF(AND(IA$4>=$C25,IA$4<$D25),"R",IF(AND(IA$4>=$D25,IA$4<$E25),"P",IF(AND(IA$4>=$E25,IA$4<$F25),"T","")))
A26: 21 | B26: =Premissas!$B$6 -> 6 | C26: =20*Premissas!$B$8 -> 242.42424 | D26: =C26+Premissas!$B$9 -> 290.42424 | E26: =C26+Premissas!$B$11 -> 296.42424 | F26: =E26+Premissas!$B$8 -> 308.54545 | G26: =Premissas!$B$11 -> 54 | H26: =Premissas!$B$12 -> 3 | I26: PLANEJADA | J26: Slot serial; criação imutável. | K26: =IF(AND(K$4>=$C26,K$4<$D26),"R",IF(AND(K$4>=$D26,K$4<$E26),"P",IF(AND(K$4>=$E26,K$4<$F26),"T",""))) | L26: =IF(AND(L$4>=$C26,L$4<$D26),"R",IF(AND(L$4>=$D26,L$4<$E26),"P",IF(AND(L$4>=$E26,L$4<$F26),"T",""))) | M26: =IF(AND(M$4>=$C26,M$4<$D26),"R",IF(AND(M$4>=$D26,M$4<$E26),"P",IF(AND(M$4>=$E26,M$4<$F26),"T",""))) | N26: =IF(AND(N$4>=$C26,N$4<$D26),"R",IF(AND(N$4>=$D26,N$4<$E26),"P",IF(AND(N$4>=$E26,N$4<$F26),"T",""))) | O26: =IF(AND(O$4>=$C26,O$4<$D26),"R",IF(AND(O$4>=$D26,O$4<$E26),"P",IF(AND(O$4>=$E26,O$4<$F26),"T",""))) | P26: =IF(AND(P$4>=$C26,P$4<$D26),"R",IF(AND(P$4>=$D26,P$4<$E26),"P",IF(AND(P$4>=$E26,P$4<$F26),"T",""))) | Q26: =IF(AND(Q$4>=$C26,Q$4<$D26),"R",IF(AND(Q$4>=$D26,Q$4<$E26),"P",IF(AND(Q$4>=$E26,Q$4<$F26),"T",""))) | R26: =IF(AND(R$4>=$C26,R$4<$D26),"R",IF(AND(R$4>=$D26,R$4<$E26),"P",IF(AND(R$4>=$E26,R$4<$F26),"T",""))) | ... IA26: =IF(AND(IA$4>=$C26,IA$4<$D26),"R",IF(AND(IA$4>=$D26,IA$4<$E26),"P",IF(AND(IA$4>=$E26,IA$4<$F26),"T","")))
A27: 22 | B27: =Premissas!$B$6 -> 6 | C27: =21*Premissas!$B$8 -> 254.54545 | D27: =C27+Premissas!$B$9 -> 302.54545 | E27: =C27+Premissas!$B$11 -> 308.54545 | F27: =E27+Premissas!$B$8 -> 320.66667 | G27: =Premissas!$B$11 -> 54 | H27: =Premissas!$B$12 -> 3 | I27: PLANEJADA | J27: Slot serial; criação imutável. | K27: =IF(AND(K$4>=$C27,K$4<$D27),"R",IF(AND(K$4>=$D27,K$4<$E27),"P",IF(AND(K$4>=$E27,K$4<$F27),"T",""))) | L27: =IF(AND(L$4>=$C27,L$4<$D27),"R",IF(AND(L$4>=$D27,L$4<$E27),"P",IF(AND(L$4>=$E27,L$4<$F27),"T",""))) | M27: =IF(AND(M$4>=$C27,M$4<$D27),"R",IF(AND(M$4>=$D27,M$4<$E27),"P",IF(AND(M$4>=$E27,M$4<$F27),"T",""))) | N27: =IF(AND(N$4>=$C27,N$4<$D27),"R",IF(AND(N$4>=$D27,N$4<$E27),"P",IF(AND(N$4>=$E27,N$4<$F27),"T",""))) | O27: =IF(AND(O$4>=$C27,O$4<$D27),"R",IF(AND(O$4>=$D27,O$4<$E27),"P",IF(AND(O$4>=$E27,O$4<$F27),"T",""))) | P27: =IF(AND(P$4>=$C27,P$4<$D27),"R",IF(AND(P$4>=$D27,P$4<$E27),"P",IF(AND(P$4>=$E27,P$4<$F27),"T",""))) | Q27: =IF(AND(Q$4>=$C27,Q$4<$D27),"R",IF(AND(Q$4>=$D27,Q$4<$E27),"P",IF(AND(Q$4>=$E27,Q$4<$F27),"T",""))) | R27: =IF(AND(R$4>=$C27,R$4<$D27),"R",IF(AND(R$4>=$D27,R$4<$E27),"P",IF(AND(R$4>=$E27,R$4<$F27),"T",""))) | ... IA27: =IF(AND(IA$4>=$C27,IA$4<$D27),"R",IF(AND(IA$4>=$D27,IA$4<$E27),"P",IF(AND(IA$4>=$E27,IA$4<$F27),"T","")))
A28: 23 | B28: =Premissas!$B$6 -> 6 | C28: =22*Premissas!$B$8 -> 266.66667 | D28: =C28+Premissas!$B$9 -> 314.66667 | E28: =C28+Premissas!$B$11 -> 320.66667 | F28: =E28+Premissas!$B$8 -> 332.78788 | G28: =Premissas!$B$11 -> 54 | H28: =Premissas!$B$12 -> 3 | I28: PLANEJADA | J28: Slot serial; criação imutável. | K28: =IF(AND(K$4>=$C28,K$4<$D28),"R",IF(AND(K$4>=$D28,K$4<$E28),"P",IF(AND(K$4>=$E28,K$4<$F28),"T",""))) | L28: =IF(AND(L$4>=$C28,L$4<$D28),"R",IF(AND(L$4>=$D28,L$4<$E28),"P",IF(AND(L$4>=$E28,L$4<$F28),"T",""))) | M28: =IF(AND(M$4>=$C28,M$4<$D28),"R",IF(AND(M$4>=$D28,M$4<$E28),"P",IF(AND(M$4>=$E28,M$4<$F28),"T",""))) | N28: =IF(AND(N$4>=$C28,N$4<$D28),"R",IF(AND(N$4>=$D28,N$4<$E28),"P",IF(AND(N$4>=$E28,N$4<$F28),"T",""))) | O28: =IF(AND(O$4>=$C28,O$4<$D28),"R",IF(AND(O$4>=$D28,O$4<$E28),"P",IF(AND(O$4>=$E28,O$4<$F28),"T",""))) | P28: =IF(AND(P$4>=$C28,P$4<$D28),"R",IF(AND(P$4>=$D28,P$4<$E28),"P",IF(AND(P$4>=$E28,P$4<$F28),"T",""))) | Q28: =IF(AND(Q$4>=$C28,Q$4<$D28),"R",IF(AND(Q$4>=$D28,Q$4<$E28),"P",IF(AND(Q$4>=$E28,Q$4<$F28),"T",""))) | R28: =IF(AND(R$4>=$C28,R$4<$D28),"R",IF(AND(R$4>=$D28,R$4<$E28),"P",IF(AND(R$4>=$E28,R$4<$F28),"T",""))) | ... IA28: =IF(AND(IA$4>=$C28,IA$4<$D28),"R",IF(AND(IA$4>=$D28,IA$4<$E28),"P",IF(AND(IA$4>=$E28,IA$4<$F28),"T","")))
A29: 24 | B29: =Premissas!$B$6 -> 6 | C29: =23*Premissas!$B$8 -> 278.78788 | D29: =C29+Premissas!$B$9 -> 326.78788 | E29: =C29+Premissas!$B$11 -> 332.78788 | F29: =E29+Premissas!$B$8 -> 344.90909 | G29: =Premissas!$B$11 -> 54 | H29: =Premissas!$B$12 -> 3 | I29: PLANEJADA | J29: Slot serial; criação imutável. | K29: =IF(AND(K$4>=$C29,K$4<$D29),"R",IF(AND(K$4>=$D29,K$4<$E29),"P",IF(AND(K$4>=$E29,K$4<$F29),"T",""))) | L29: =IF(AND(L$4>=$C29,L$4<$D29),"R",IF(AND(L$4>=$D29,L$4<$E29),"P",IF(AND(L$4>=$E29,L$4<$F29),"T",""))) | M29: =IF(AND(M$4>=$C29,M$4<$D29),"R",IF(AND(M$4>=$D29,M$4<$E29),"P",IF(AND(M$4>=$E29,M$4<$F29),"T",""))) | N29: =IF(AND(N$4>=$C29,N$4<$D29),"R",IF(AND(N$4>=$D29,N$4<$E29),"P",IF(AND(N$4>=$E29,N$4<$F29),"T",""))) | O29: =IF(AND(O$4>=$C29,O$4<$D29),"R",IF(AND(O$4>=$D29,O$4<$E29),"P",IF(AND(O$4>=$E29,O$4<$F29),"T",""))) | P29: =IF(AND(P$4>=$C29,P$4<$D29),"R",IF(AND(P$4>=$D29,P$4<$E29),"P",IF(AND(P$4>=$E29,P$4<$F29),"T",""))) | Q29: =IF(AND(Q$4>=$C29,Q$4<$D29),"R",IF(AND(Q$4>=$D29,Q$4<$E29),"P",IF(AND(Q$4>=$E29,Q$4<$F29),"T",""))) | R29: =IF(AND(R$4>=$C29,R$4<$D29),"R",IF(AND(R$4>=$D29,R$4<$E29),"P",IF(AND(R$4>=$E29,R$4<$F29),"T",""))) | ... IA29: =IF(AND(IA$4>=$C29,IA$4<$D29),"R",IF(AND(IA$4>=$D29,IA$4<$E29),"P",IF(AND(IA$4>=$E29,IA$4<$F29),"T","")))
A30: 25 | B30: =Premissas!$B$6 -> 6 | C30: =24*Premissas!$B$8 -> 290.90909 | D30: =C30+Premissas!$B$9 -> 338.90909 | E30: =C30+Premissas!$B$11 -> 344.90909 | F30: =E30+Premissas!$B$8 -> 357.0303 | G30: =Premissas!$B$11 -> 54 | H30: =Premissas!$B$12 -> 3 | I30: PLANEJADA | J30: Slot serial; criação imutável. | K30: =IF(AND(K$4>=$C30,K$4<$D30),"R",IF(AND(K$4>=$D30,K$4<$E30),"P",IF(AND(K$4>=$E30,K$4<$F30),"T",""))) | L30: =IF(AND(L$4>=$C30,L$4<$D30),"R",IF(AND(L$4>=$D30,L$4<$E30),"P",IF(AND(L$4>=$E30,L$4<$F30),"T",""))) | M30: =IF(AND(M$4>=$C30,M$4<$D30),"R",IF(AND(M$4>=$D30,M$4<$E30),"P",IF(AND(M$4>=$E30,M$4<$F30),"T",""))) | N30: =IF(AND(N$4>=$C30,N$4<$D30),"R",IF(AND(N$4>=$D30,N$4<$E30),"P",IF(AND(N$4>=$E30,N$4<$F30),"T",""))) | O30: =IF(AND(O$4>=$C30,O$4<$D30),"R",IF(AND(O$4>=$D30,O$4<$E30),"P",IF(AND(O$4>=$E30,O$4<$F30),"T",""))) | P30: =IF(AND(P$4>=$C30,P$4<$D30),"R",IF(AND(P$4>=$D30,P$4<$E30),"P",IF(AND(P$4>=$E30,P$4<$F30),"T",""))) | Q30: =IF(AND(Q$4>=$C30,Q$4<$D30),"R",IF(AND(Q$4>=$D30,Q$4<$E30),"P",IF(AND(Q$4>=$E30,Q$4<$F30),"T",""))) | R30: =IF(AND(R$4>=$C30,R$4<$D30),"R",IF(AND(R$4>=$D30,R$4<$E30),"P",IF(AND(R$4>=$E30,R$4<$F30),"T",""))) | ... IA30: =IF(AND(IA$4>=$C30,IA$4<$D30),"R",IF(AND(IA$4>=$D30,IA$4<$E30),"P",IF(AND(IA$4>=$E30,IA$4<$F30),"T","")))
A31: 26 | B31: =Premissas!$B$6 -> 6 | C31: =25*Premissas!$B$8 -> 303.0303 | D31: =C31+Premissas!$B$9 -> 351.0303 | E31: =C31+Premissas!$B$11 -> 357.0303 | F31: =E31+Premissas!$B$8 -> 369.15152 | G31: =Premissas!$B$11 -> 54 | H31: =Premissas!$B$12 -> 3 | I31: PLANEJADA | J31: Slot serial; criação imutável. | K31: =IF(AND(K$4>=$C31,K$4<$D31),"R",IF(AND(K$4>=$D31,K$4<$E31),"P",IF(AND(K$4>=$E31,K$4<$F31),"T",""))) | L31: =IF(AND(L$4>=$C31,L$4<$D31),"R",IF(AND(L$4>=$D31,L$4<$E31),"P",IF(AND(L$4>=$E31,L$4<$F31),"T",""))) | M31: =IF(AND(M$4>=$C31,M$4<$D31),"R",IF(AND(M$4>=$D31,M$4<$E31),"P",IF(AND(M$4>=$E31,M$4<$F31),"T",""))) | N31: =IF(AND(N$4>=$C31,N$4<$D31),"R",IF(AND(N$4>=$D31,N$4<$E31),"P",IF(AND(N$4>=$E31,N$4<$F31),"T",""))) | O31: =IF(AND(O$4>=$C31,O$4<$D31),"R",IF(AND(O$4>=$D31,O$4<$E31),"P",IF(AND(O$4>=$E31,O$4<$F31),"T",""))) | P31: =IF(AND(P$4>=$C31,P$4<$D31),"R",IF(AND(P$4>=$D31,P$4<$E31),"P",IF(AND(P$4>=$E31,P$4<$F31),"T",""))) | Q31: =IF(AND(Q$4>=$C31,Q$4<$D31),"R",IF(AND(Q$4>=$D31,Q$4<$E31),"P",IF(AND(Q$4>=$E31,Q$4<$F31),"T",""))) | R31: =IF(AND(R$4>=$C31,R$4<$D31),"R",IF(AND(R$4>=$D31,R$4<$E31),"P",IF(AND(R$4>=$E31,R$4<$F31),"T",""))) | ... IA31: =IF(AND(IA$4>=$C31,IA$4<$D31),"R",IF(AND(IA$4>=$D31,IA$4<$E31),"P",IF(AND(IA$4>=$E31,IA$4<$F31),"T","")))
A32: 27 | B32: =Premissas!$B$6 -> 6 | C32: =26*Premissas!$B$8 -> 315.15152 | D32: =C32+Premissas!$B$9 -> 363.15152 | E32: =C32+Premissas!$B$11 -> 369.15152 | F32: =E32+Premissas!$B$8 -> 381.27273 | G32: =Premissas!$B$11 -> 54 | H32: =Premissas!$B$12 -> 3 | I32: PLANEJADA | J32: Slot serial; criação imutável. | K32: =IF(AND(K$4>=$C32,K$4<$D32),"R",IF(AND(K$4>=$D32,K$4<$E32),"P",IF(AND(K$4>=$E32,K$4<$F32),"T",""))) | L32: =IF(AND(L$4>=$C32,L$4<$D32),"R",IF(AND(L$4>=$D32,L$4<$E32),"P",IF(AND(L$4>=$E32,L$4<$F32),"T",""))) | M32: =IF(AND(M$4>=$C32,M$4<$D32),"R",IF(AND(M$4>=$D32,M$4<$E32),"P",IF(AND(M$4>=$E32,M$4<$F32),"T",""))) | N32: =IF(AND(N$4>=$C32,N$4<$D32),"R",IF(AND(N$4>=$D32,N$4<$E32),"P",IF(AND(N$4>=$E32,N$4<$F32),"T",""))) | O32: =IF(AND(O$4>=$C32,O$4<$D32),"R",IF(AND(O$4>=$D32,O$4<$E32),"P",IF(AND(O$4>=$E32,O$4<$F32),"T",""))) | P32: =IF(AND(P$4>=$C32,P$4<$D32),"R",IF(AND(P$4>=$D32,P$4<$E32),"P",IF(AND(P$4>=$E32,P$4<$F32),"T",""))) | Q32: =IF(AND(Q$4>=$C32,Q$4<$D32),"R",IF(AND(Q$4>=$D32,Q$4<$E32),"P",IF(AND(Q$4>=$E32,Q$4<$F32),"T",""))) | R32: =IF(AND(R$4>=$C32,R$4<$D32),"R",IF(AND(R$4>=$D32,R$4<$E32),"P",IF(AND(R$4>=$E32,R$4<$F32),"T",""))) | ... IA32: =IF(AND(IA$4>=$C32,IA$4<$D32),"R",IF(AND(IA$4>=$D32,IA$4<$E32),"P",IF(AND(IA$4>=$E32,IA$4<$F32),"T","")))
A33: 28 | B33: =Premissas!$B$6 -> 6 | C33: =27*Premissas!$B$8 -> 327.27273 | D33: =C33+Premissas!$B$9 -> 375.27273 | E33: =C33+Premissas!$B$11 -> 381.27273 | F33: =E33+Premissas!$B$8 -> 393.39394 | G33: =Premissas!$B$11 -> 54 | H33: =Premissas!$B$12 -> 3 | I33: PLANEJADA | J33: Slot serial; criação imutável. | K33: =IF(AND(K$4>=$C33,K$4<$D33),"R",IF(AND(K$4>=$D33,K$4<$E33),"P",IF(AND(K$4>=$E33,K$4<$F33),"T",""))) | L33: =IF(AND(L$4>=$C33,L$4<$D33),"R",IF(AND(L$4>=$D33,L$4<$E33),"P",IF(AND(L$4>=$E33,L$4<$F33),"T",""))) | M33: =IF(AND(M$4>=$C33,M$4<$D33),"R",IF(AND(M$4>=$D33,M$4<$E33),"P",IF(AND(M$4>=$E33,M$4<$F33),"T",""))) | N33: =IF(AND(N$4>=$C33,N$4<$D33),"R",IF(AND(N$4>=$D33,N$4<$E33),"P",IF(AND(N$4>=$E33,N$4<$F33),"T",""))) | O33: =IF(AND(O$4>=$C33,O$4<$D33),"R",IF(AND(O$4>=$D33,O$4<$E33),"P",IF(AND(O$4>=$E33,O$4<$F33),"T",""))) | P33: =IF(AND(P$4>=$C33,P$4<$D33),"R",IF(AND(P$4>=$D33,P$4<$E33),"P",IF(AND(P$4>=$E33,P$4<$F33),"T",""))) | Q33: =IF(AND(Q$4>=$C33,Q$4<$D33),"R",IF(AND(Q$4>=$D33,Q$4<$E33),"P",IF(AND(Q$4>=$E33,Q$4<$F33),"T",""))) | R33: =IF(AND(R$4>=$C33,R$4<$D33),"R",IF(AND(R$4>=$D33,R$4<$E33),"P",IF(AND(R$4>=$E33,R$4<$F33),"T",""))) | ... IA33: =IF(AND(IA$4>=$C33,IA$4<$D33),"R",IF(AND(IA$4>=$D33,IA$4<$E33),"P",IF(AND(IA$4>=$E33,IA$4<$F33),"T","")))
A34: 29 | B34: =Premissas!$B$6 -> 6 | C34: =28*Premissas!$B$8 -> 339.39394 | D34: =C34+Premissas!$B$9 -> 387.39394 | E34: =C34+Premissas!$B$11 -> 393.39394 | F34: =E34+Premissas!$B$8 -> 405.51515 | G34: =Premissas!$B$11 -> 54 | H34: =Premissas!$B$12 -> 3 | I34: PLANEJADA | J34: Slot serial; criação imutável. | K34: =IF(AND(K$4>=$C34,K$4<$D34),"R",IF(AND(K$4>=$D34,K$4<$E34),"P",IF(AND(K$4>=$E34,K$4<$F34),"T",""))) | L34: =IF(AND(L$4>=$C34,L$4<$D34),"R",IF(AND(L$4>=$D34,L$4<$E34),"P",IF(AND(L$4>=$E34,L$4<$F34),"T",""))) | M34: =IF(AND(M$4>=$C34,M$4<$D34),"R",IF(AND(M$4>=$D34,M$4<$E34),"P",IF(AND(M$4>=$E34,M$4<$F34),"T",""))) | N34: =IF(AND(N$4>=$C34,N$4<$D34),"R",IF(AND(N$4>=$D34,N$4<$E34),"P",IF(AND(N$4>=$E34,N$4<$F34),"T",""))) | O34: =IF(AND(O$4>=$C34,O$4<$D34),"R",IF(AND(O$4>=$D34,O$4<$E34),"P",IF(AND(O$4>=$E34,O$4<$F34),"T",""))) | P34: =IF(AND(P$4>=$C34,P$4<$D34),"R",IF(AND(P$4>=$D34,P$4<$E34),"P",IF(AND(P$4>=$E34,P$4<$F34),"T",""))) | Q34: =IF(AND(Q$4>=$C34,Q$4<$D34),"R",IF(AND(Q$4>=$D34,Q$4<$E34),"P",IF(AND(Q$4>=$E34,Q$4<$F34),"T",""))) | R34: =IF(AND(R$4>=$C34,R$4<$D34),"R",IF(AND(R$4>=$D34,R$4<$E34),"P",IF(AND(R$4>=$E34,R$4<$F34),"T",""))) | ... IA34: =IF(AND(IA$4>=$C34,IA$4<$D34),"R",IF(AND(IA$4>=$D34,IA$4<$E34),"P",IF(AND(IA$4>=$E34,IA$4<$F34),"T","")))
A35: 30 | B35: =Premissas!$B$6 -> 6 | C35: =29*Premissas!$B$8 -> 351.51515 | D35: =C35+Premissas!$B$9 -> 399.51515 | E35: =C35+Premissas!$B$11 -> 405.51515 | F35: =E35+Premissas!$B$8 -> 417.63636 | G35: =Premissas!$B$11 -> 54 | H35: =Premissas!$B$12 -> 3 | I35: PLANEJADA | J35: Slot serial; criação imutável. | K35: =IF(AND(K$4>=$C35,K$4<$D35),"R",IF(AND(K$4>=$D35,K$4<$E35),"P",IF(AND(K$4>=$E35,K$4<$F35),"T",""))) | L35: =IF(AND(L$4>=$C35,L$4<$D35),"R",IF(AND(L$4>=$D35,L$4<$E35),"P",IF(AND(L$4>=$E35,L$4<$F35),"T",""))) | M35: =IF(AND(M$4>=$C35,M$4<$D35),"R",IF(AND(M$4>=$D35,M$4<$E35),"P",IF(AND(M$4>=$E35,M$4<$F35),"T",""))) | N35: =IF(AND(N$4>=$C35,N$4<$D35),"R",IF(AND(N$4>=$D35,N$4<$E35),"P",IF(AND(N$4>=$E35,N$4<$F35),"T",""))) | O35: =IF(AND(O$4>=$C35,O$4<$D35),"R",IF(AND(O$4>=$D35,O$4<$E35),"P",IF(AND(O$4>=$E35,O$4<$F35),"T",""))) | P35: =IF(AND(P$4>=$C35,P$4<$D35),"R",IF(AND(P$4>=$D35,P$4<$E35),"P",IF(AND(P$4>=$E35,P$4<$F35),"T",""))) | Q35: =IF(AND(Q$4>=$C35,Q$4<$D35),"R",IF(AND(Q$4>=$D35,Q$4<$E35),"P",IF(AND(Q$4>=$E35,Q$4<$F35),"T",""))) | R35: =IF(AND(R$4>=$C35,R$4<$D35),"R",IF(AND(R$4>=$D35,R$4<$E35),"P",IF(AND(R$4>=$E35,R$4<$F35),"T",""))) | ... IA35: =IF(AND(IA$4>=$C35,IA$4<$D35),"R",IF(AND(IA$4>=$D35,IA$4<$E35),"P",IF(AND(IA$4>=$E35,IA$4<$F35),"T","")))
A36: 31 | B36: =Premissas!$B$6 -> 6 | C36: =30*Premissas!$B$8 -> 363.63636 | D36: =C36+Premissas!$B$9 -> 411.63636 | E36: =C36+Premissas!$B$11 -> 417.63636 | F36: =E36+Premissas!$B$8 -> 429.75758 | G36: =Premissas!$B$11 -> 54 | H36: =Premissas!$B$12 -> 3 | I36: PLANEJADA | J36: Slot serial; criação imutável. | K36: =IF(AND(K$4>=$C36,K$4<$D36),"R",IF(AND(K$4>=$D36,K$4<$E36),"P",IF(AND(K$4>=$E36,K$4<$F36),"T",""))) | L36: =IF(AND(L$4>=$C36,L$4<$D36),"R",IF(AND(L$4>=$D36,L$4<$E36),"P",IF(AND(L$4>=$E36,L$4<$F36),"T",""))) | M36: =IF(AND(M$4>=$C36,M$4<$D36),"R",IF(AND(M$4>=$D36,M$4<$E36),"P",IF(AND(M$4>=$E36,M$4<$F36),"T",""))) | N36: =IF(AND(N$4>=$C36,N$4<$D36),"R",IF(AND(N$4>=$D36,N$4<$E36),"P",IF(AND(N$4>=$E36,N$4<$F36),"T",""))) | O36: =IF(AND(O$4>=$C36,O$4<$D36),"R",IF(AND(O$4>=$D36,O$4<$E36),"P",IF(AND(O$4>=$E36,O$4<$F36),"T",""))) | P36: =IF(AND(P$4>=$C36,P$4<$D36),"R",IF(AND(P$4>=$D36,P$4<$E36),"P",IF(AND(P$4>=$E36,P$4<$F36),"T",""))) | Q36: =IF(AND(Q$4>=$C36,Q$4<$D36),"R",IF(AND(Q$4>=$D36,Q$4<$E36),"P",IF(AND(Q$4>=$E36,Q$4<$F36),"T",""))) | R36: =IF(AND(R$4>=$C36,R$4<$D36),"R",IF(AND(R$4>=$D36,R$4<$E36),"P",IF(AND(R$4>=$E36,R$4<$F36),"T",""))) | ... IA36: =IF(AND(IA$4>=$C36,IA$4<$D36),"R",IF(AND(IA$4>=$D36,IA$4<$E36),"P",IF(AND(IA$4>=$E36,IA$4<$F36),"T","")))
A37: 32 | B37: =Premissas!$B$6 -> 6 | C37: =31*Premissas!$B$8 -> 375.75758 | D37: =C37+Premissas!$B$9 -> 423.75758 | E37: =C37+Premissas!$B$11 -> 429.75758 | F37: =E37+Premissas!$B$8 -> 441.87879 | G37: =Premissas!$B$11 -> 54 | H37: =Premissas!$B$12 -> 3 | I37: PLANEJADA | J37: Slot serial; criação imutável. | K37: =IF(AND(K$4>=$C37,K$4<$D37),"R",IF(AND(K$4>=$D37,K$4<$E37),"P",IF(AND(K$4>=$E37,K$4<$F37),"T",""))) | L37: =IF(AND(L$4>=$C37,L$4<$D37),"R",IF(AND(L$4>=$D37,L$4<$E37),"P",IF(AND(L$4>=$E37,L$4<$F37),"T",""))) | M37: =IF(AND(M$4>=$C37,M$4<$D37),"R",IF(AND(M$4>=$D37,M$4<$E37),"P",IF(AND(M$4>=$E37,M$4<$F37),"T",""))) | N37: =IF(AND(N$4>=$C37,N$4<$D37),"R",IF(AND(N$4>=$D37,N$4<$E37),"P",IF(AND(N$4>=$E37,N$4<$F37),"T",""))) | O37: =IF(AND(O$4>=$C37,O$4<$D37),"R",IF(AND(O$4>=$D37,O$4<$E37),"P",IF(AND(O$4>=$E37,O$4<$F37),"T",""))) | P37: =IF(AND(P$4>=$C37,P$4<$D37),"R",IF(AND(P$4>=$D37,P$4<$E37),"P",IF(AND(P$4>=$E37,P$4<$F37),"T",""))) | Q37: =IF(AND(Q$4>=$C37,Q$4<$D37),"R",IF(AND(Q$4>=$D37,Q$4<$E37),"P",IF(AND(Q$4>=$E37,Q$4<$F37),"T",""))) | R37: =IF(AND(R$4>=$C37,R$4<$D37),"R",IF(AND(R$4>=$D37,R$4<$E37),"P",IF(AND(R$4>=$E37,R$4<$F37),"T",""))) | ... IA37: =IF(AND(IA$4>=$C37,IA$4<$D37),"R",IF(AND(IA$4>=$D37,IA$4<$E37),"P",IF(AND(IA$4>=$E37,IA$4<$F37),"T","")))
A38: 33 | B38: =Premissas!$B$6 -> 6 | C38: =32*Premissas!$B$8 -> 387.87879 | D38: =C38+Premissas!$B$9 -> 435.87879 | E38: =C38+Premissas!$B$11 -> 441.87879 | F38: =E38+Premissas!$B$8 -> 454 | G38: =Premissas!$B$11 -> 54 | H38: =Premissas!$B$12 -> 3 | I38: PLANEJADA | J38: Slot serial; criação imutável. | K38: =IF(AND(K$4>=$C38,K$4<$D38),"R",IF(AND(K$4>=$D38,K$4<$E38),"P",IF(AND(K$4>=$E38,K$4<$F38),"T",""))) | L38: =IF(AND(L$4>=$C38,L$4<$D38),"R",IF(AND(L$4>=$D38,L$4<$E38),"P",IF(AND(L$4>=$E38,L$4<$F38),"T",""))) | M38: =IF(AND(M$4>=$C38,M$4<$D38),"R",IF(AND(M$4>=$D38,M$4<$E38),"P",IF(AND(M$4>=$E38,M$4<$F38),"T",""))) | N38: =IF(AND(N$4>=$C38,N$4<$D38),"R",IF(AND(N$4>=$D38,N$4<$E38),"P",IF(AND(N$4>=$E38,N$4<$F38),"T",""))) | O38: =IF(AND(O$4>=$C38,O$4<$D38),"R",IF(AND(O$4>=$D38,O$4<$E38),"P",IF(AND(O$4>=$E38,O$4<$F38),"T",""))) | P38: =IF(AND(P$4>=$C38,P$4<$D38),"R",IF(AND(P$4>=$D38,P$4<$E38),"P",IF(AND(P$4>=$E38,P$4<$F38),"T",""))) | Q38: =IF(AND(Q$4>=$C38,Q$4<$D38),"R",IF(AND(Q$4>=$D38,Q$4<$E38),"P",IF(AND(Q$4>=$E38,Q$4<$F38),"T",""))) | R38: =IF(AND(R$4>=$C38,R$4<$D38),"R",IF(AND(R$4>=$D38,R$4<$E38),"P",IF(AND(R$4>=$E38,R$4<$F38),"T",""))) | ... IA38: =IF(AND(IA$4>=$C38,IA$4<$D38),"R",IF(AND(IA$4>=$D38,IA$4<$E38),"P",IF(AND(IA$4>=$E38,IA$4<$F38),"T","")))
A39: 34 | B39: =Premissas!$B$6 -> 6 | C39: =33*Premissas!$B$8 -> 400 | D39: =C39+Premissas!$B$9 -> 448 | E39: =C39+Premissas!$B$11 -> 454 | F39: =E39+Premissas!$B$8 -> 466.12121 | G39: =Premissas!$B$11 -> 54 | H39: =Premissas!$B$12 -> 3 | I39: PLANEJADA | J39: Slot serial; criação imutável. | K39: =IF(AND(K$4>=$C39,K$4<$D39),"R",IF(AND(K$4>=$D39,K$4<$E39),"P",IF(AND(K$4>=$E39,K$4<$F39),"T",""))) | L39: =IF(AND(L$4>=$C39,L$4<$D39),"R",IF(AND(L$4>=$D39,L$4<$E39),"P",IF(AND(L$4>=$E39,L$4<$F39),"T",""))) | M39: =IF(AND(M$4>=$C39,M$4<$D39),"R",IF(AND(M$4>=$D39,M$4<$E39),"P",IF(AND(M$4>=$E39,M$4<$F39),"T",""))) | N39: =IF(AND(N$4>=$C39,N$4<$D39),"R",IF(AND(N$4>=$D39,N$4<$E39),"P",IF(AND(N$4>=$E39,N$4<$F39),"T",""))) | O39: =IF(AND(O$4>=$C39,O$4<$D39),"R",IF(AND(O$4>=$D39,O$4<$E39),"P",IF(AND(O$4>=$E39,O$4<$F39),"T",""))) | P39: =IF(AND(P$4>=$C39,P$4<$D39),"R",IF(AND(P$4>=$D39,P$4<$E39),"P",IF(AND(P$4>=$E39,P$4<$F39),"T",""))) | Q39: =IF(AND(Q$4>=$C39,Q$4<$D39),"R",IF(AND(Q$4>=$D39,Q$4<$E39),"P",IF(AND(Q$4>=$E39,Q$4<$F39),"T",""))) | R39: =IF(AND(R$4>=$C39,R$4<$D39),"R",IF(AND(R$4>=$D39,R$4<$E39),"P",IF(AND(R$4>=$E39,R$4<$F39),"T",""))) | ... IA39: =IF(AND(IA$4>=$C39,IA$4<$D39),"R",IF(AND(IA$4>=$D39,IA$4<$E39),"P",IF(AND(IA$4>=$E39,IA$4<$F39),"T","")))
A40: 35 | B40: =Premissas!$B$6 -> 6 | C40: =34*Premissas!$B$8 -> 412.12121 | D40: =C40+Premissas!$B$9 -> 460.12121 | E40: =C40+Premissas!$B$11 -> 466.12121 | F40: =E40+Premissas!$B$8 -> 478.24242 | G40: =Premissas!$B$11 -> 54 | H40: =Premissas!$B$12 -> 3 | I40: PLANEJADA | J40: Slot serial; criação imutável. | K40: =IF(AND(K$4>=$C40,K$4<$D40),"R",IF(AND(K$4>=$D40,K$4<$E40),"P",IF(AND(K$4>=$E40,K$4<$F40),"T",""))) | L40: =IF(AND(L$4>=$C40,L$4<$D40),"R",IF(AND(L$4>=$D40,L$4<$E40),"P",IF(AND(L$4>=$E40,L$4<$F40),"T",""))) | M40: =IF(AND(M$4>=$C40,M$4<$D40),"R",IF(AND(M$4>=$D40,M$4<$E40),"P",IF(AND(M$4>=$E40,M$4<$F40),"T",""))) | N40: =IF(AND(N$4>=$C40,N$4<$D40),"R",IF(AND(N$4>=$D40,N$4<$E40),"P",IF(AND(N$4>=$E40,N$4<$F40),"T",""))) | O40: =IF(AND(O$4>=$C40,O$4<$D40),"R",IF(AND(O$4>=$D40,O$4<$E40),"P",IF(AND(O$4>=$E40,O$4<$F40),"T",""))) | P40: =IF(AND(P$4>=$C40,P$4<$D40),"R",IF(AND(P$4>=$D40,P$4<$E40),"P",IF(AND(P$4>=$E40,P$4<$F40),"T",""))) | Q40: =IF(AND(Q$4>=$C40,Q$4<$D40),"R",IF(AND(Q$4>=$D40,Q$4<$E40),"P",IF(AND(Q$4>=$E40,Q$4<$F40),"T",""))) | R40: =IF(AND(R$4>=$C40,R$4<$D40),"R",IF(AND(R$4>=$D40,R$4<$E40),"P",IF(AND(R$4>=$E40,R$4<$F40),"T",""))) | ... IA40: =IF(AND(IA$4>=$C40,IA$4<$D40),"R",IF(AND(IA$4>=$D40,IA$4<$E40),"P",IF(AND(IA$4>=$E40,IA$4<$F40),"T","")))
A41: 36 | B41: =Premissas!$B$6 -> 6 | C41: =35*Premissas!$B$8 -> 424.24242 | D41: =C41+Premissas!$B$9 -> 472.24242 | E41: =C41+Premissas!$B$11 -> 478.24242 | F41: =E41+Premissas!$B$8 -> 490.36364 | G41: =Premissas!$B$11 -> 54 | H41: =Premissas!$B$12 -> 3 | I41: PLANEJADA | J41: Slot serial; criação imutável. | K41: =IF(AND(K$4>=$C41,K$4<$D41),"R",IF(AND(K$4>=$D41,K$4<$E41),"P",IF(AND(K$4>=$E41,K$4<$F41),"T",""))) | L41: =IF(AND(L$4>=$C41,L$4<$D41),"R",IF(AND(L$4>=$D41,L$4<$E41),"P",IF(AND(L$4>=$E41,L$4<$F41),"T",""))) | M41: =IF(AND(M$4>=$C41,M$4<$D41),"R",IF(AND(M$4>=$D41,M$4<$E41),"P",IF(AND(M$4>=$E41,M$4<$F41),"T",""))) | N41: =IF(AND(N$4>=$C41,N$4<$D41),"R",IF(AND(N$4>=$D41,N$4<$E41),"P",IF(AND(N$4>=$E41,N$4<$F41),"T",""))) | O41: =IF(AND(O$4>=$C41,O$4<$D41),"R",IF(AND(O$4>=$D41,O$4<$E41),"P",IF(AND(O$4>=$E41,O$4<$F41),"T",""))) | P41: =IF(AND(P$4>=$C41,P$4<$D41),"R",IF(AND(P$4>=$D41,P$4<$E41),"P",IF(AND(P$4>=$E41,P$4<$F41),"T",""))) | Q41: =IF(AND(Q$4>=$C41,Q$4<$D41),"R",IF(AND(Q$4>=$D41,Q$4<$E41),"P",IF(AND(Q$4>=$E41,Q$4<$F41),"T",""))) | R41: =IF(AND(R$4>=$C41,R$4<$D41),"R",IF(AND(R$4>=$D41,R$4<$E41),"P",IF(AND(R$4>=$E41,R$4<$F41),"T",""))) | ... IA41: =IF(AND(IA$4>=$C41,IA$4<$D41),"R",IF(AND(IA$4>=$D41,IA$4<$E41),"P",IF(AND(IA$4>=$E41,IA$4<$F41),"T","")))
...

Sheet Legenda
A1: Legenda e regras operacionais
A4: R — Restore em andamento | B4: A solicitação foi enviada ao S3 Batch Operations; o objeto ainda pode estar indisponível.
A5: P — Pronta / margem | B5: Disponibilidade planejada após até 48h. Representa a margem até o slot de cópia; não significa que todos os objetos necessariamente já estejam prontos.
A6: T — Transferência | B6: A única wave em cópia; todos os workers configurados podem atuar nela.
A7: Lead time | B7: 48h de restore BULK planejado + 6h de margem. É a antecedência mínima adotada para reservar o slot de transferência.
A8: Retenção | B8: Período em que a cópia temporária restaurada permanece acessível no S3. Nesta simulação: 3 dias / 72h.
A9: Agendamento dinâmico | B9: Em produção, o tamanho das próximas waves é recalculado com vazão, quantidade de objetos, overhead por arquivo e histórico real. Waves já criadas não mudam.
A12: Limitações intencionais desta visualização
A13: A planilha representa um plano determinístico de referência. Na execução real, o Raijin registra a disponibilidade efetiva e a expiração de cada restore, recalcula as previsões com estatísticas conservadoras e alerta caso uma wave futura esteja em risco de criar lacuna. O Gantt usa blocos de 3 horas, portanto valores parciais são arredondados visualmente.
